[2022-12-14T10:40:33.227+0000] {taskinstance.py:1087} INFO - Dependencies all met for <TaskInstance: incident_etl.etl_incident scheduled__2022-12-13T00:00:00+00:00 [queued]>
[2022-12-14T10:40:33.250+0000] {taskinstance.py:1087} INFO - Dependencies all met for <TaskInstance: incident_etl.etl_incident scheduled__2022-12-13T00:00:00+00:00 [queued]>
[2022-12-14T10:40:33.250+0000] {taskinstance.py:1283} INFO - 
--------------------------------------------------------------------------------
[2022-12-14T10:40:33.250+0000] {taskinstance.py:1284} INFO - Starting attempt 1 of 1
[2022-12-14T10:40:33.250+0000] {taskinstance.py:1285} INFO - 
--------------------------------------------------------------------------------
[2022-12-14T10:40:33.280+0000] {taskinstance.py:1304} INFO - Executing <Task(BashOperator): etl_incident> on 2022-12-13 00:00:00+00:00
[2022-12-14T10:40:33.313+0000] {standard_task_runner.py:55} INFO - Started process 268 to run task
[2022-12-14T10:40:33.427+0000] {standard_task_runner.py:82} INFO - Running: ['***', 'tasks', 'run', 'incident_etl', 'etl_incident', 'scheduled__2022-12-13T00:00:00+00:00', '--job-id', '49', '--raw', '--subdir', 'DAGS_FOLDER/dag_etl_incident.py', '--cfg-path', '/tmp/tmpnc8rvnl8']
[2022-12-14T10:40:33.430+0000] {standard_task_runner.py:83} INFO - Job 49: Subtask etl_incident
[2022-12-14T10:40:33.992+0000] {task_command.py:389} INFO - Running <TaskInstance: incident_etl.etl_incident scheduled__2022-12-13T00:00:00+00:00 [running]> on host 1f859f359fd5
[2022-12-14T10:40:34.188+0000] {taskinstance.py:1513} INFO - Exporting the following env vars:
AIRFLOW_CTX_DAG_OWNER=noe
AIRFLOW_CTX_DAG_ID=incident_etl
AIRFLOW_CTX_TASK_ID=etl_incident
AIRFLOW_CTX_EXECUTION_DATE=2022-12-13T00:00:00+00:00
AIRFLOW_CTX_TRY_NUMBER=1
AIRFLOW_CTX_DAG_RUN_ID=scheduled__2022-12-13T00:00:00+00:00
[2022-12-14T10:40:34.192+0000] {subprocess.py:63} INFO - Tmp dir root location: 
 /tmp
[2022-12-14T10:40:34.194+0000] {subprocess.py:75} INFO - Running command: ['/bin/bash', '-c', 'python /opt/***/dags/etl/etl_incident.py']
[2022-12-14T10:40:34.230+0000] {subprocess.py:86} INFO - Output:
[2022-12-14T10:40:37.968+0000] {subprocess.py:93} INFO - Traceback (most recent call last):
[2022-12-14T10:40:37.968+0000] {subprocess.py:93} INFO -   File "/home/***/.local/lib/python3.7/site-packages/pandas/core/indexes/base.py", line 3361, in get_loc
[2022-12-14T10:40:37.968+0000] {subprocess.py:93} INFO -     return self._engine.get_loc(casted_key)
[2022-12-14T10:40:37.968+0000] {subprocess.py:93} INFO -   File "pandas/_libs/index.pyx", line 76, in pandas._libs.index.IndexEngine.get_loc
[2022-12-14T10:40:37.968+0000] {subprocess.py:93} INFO -   File "pandas/_libs/index.pyx", line 108, in pandas._libs.index.IndexEngine.get_loc
[2022-12-14T10:40:37.969+0000] {subprocess.py:93} INFO -   File "pandas/_libs/hashtable_class_helper.pxi", line 5198, in pandas._libs.hashtable.PyObjectHashTable.get_item
[2022-12-14T10:40:37.969+0000] {subprocess.py:93} INFO -   File "pandas/_libs/hashtable_class_helper.pxi", line 5206, in pandas._libs.hashtable.PyObjectHashTable.get_item
[2022-12-14T10:40:37.969+0000] {subprocess.py:93} INFO - KeyError: 'DateUpdated'
[2022-12-14T10:40:37.969+0000] {subprocess.py:93} INFO - 
[2022-12-14T10:40:37.969+0000] {subprocess.py:93} INFO - The above exception was the direct cause of the following exception:
[2022-12-14T10:40:37.969+0000] {subprocess.py:93} INFO - 
[2022-12-14T10:40:37.969+0000] {subprocess.py:93} INFO - Traceback (most recent call last):
[2022-12-14T10:40:37.969+0000] {subprocess.py:93} INFO -   File "/opt/***/dags/etl/etl_incident.py", line 60, in <module>
[2022-12-14T10:40:37.969+0000] {subprocess.py:93} INFO -     load_to_gcs(transform(extract_API()))
[2022-12-14T10:40:37.969+0000] {subprocess.py:93} INFO -   File "/opt/***/dags/etl/etl_incident.py", line 40, in transform
[2022-12-14T10:40:37.969+0000] {subprocess.py:93} INFO -     df['DateUpdated'] = pd.to_datetime(df['DateUpdated'])
[2022-12-14T10:40:37.970+0000] {subprocess.py:93} INFO -   File "/home/***/.local/lib/python3.7/site-packages/pandas/core/frame.py", line 3458, in __getitem__
[2022-12-14T10:40:37.970+0000] {subprocess.py:93} INFO -     indexer = self.columns.get_loc(key)
[2022-12-14T10:40:37.970+0000] {subprocess.py:93} INFO -   File "/home/***/.local/lib/python3.7/site-packages/pandas/core/indexes/base.py", line 3363, in get_loc
[2022-12-14T10:40:37.970+0000] {subprocess.py:93} INFO -     raise KeyError(key) from err
[2022-12-14T10:40:37.970+0000] {subprocess.py:93} INFO - KeyError: 'DateUpdated'
[2022-12-14T10:40:38.213+0000] {subprocess.py:97} INFO - Command exited with return code 1
[2022-12-14T10:40:38.231+0000] {taskinstance.py:1772} ERROR - Task failed with exception
Traceback (most recent call last):
  File "/home/airflow/.local/lib/python3.7/site-packages/airflow/operators/bash.py", line 197, in execute
    f"Bash command failed. The command returned a non-zero exit code {result.exit_code}."
airflow.exceptions.AirflowException: Bash command failed. The command returned a non-zero exit code 1.
[2022-12-14T10:40:38.236+0000] {taskinstance.py:1327} INFO - Marking task as FAILED. dag_id=incident_etl, task_id=etl_incident, execution_date=20221213T000000, start_date=20221214T104033, end_date=20221214T104038
[2022-12-14T10:40:38.263+0000] {standard_task_runner.py:105} ERROR - Failed to execute job 49 for task etl_incident (Bash command failed. The command returned a non-zero exit code 1.; 268)
[2022-12-14T10:40:38.436+0000] {local_task_job.py:159} INFO - Task exited with return code 1
[2022-12-14T10:40:38.473+0000] {taskinstance.py:2582} INFO - 0 downstream tasks scheduled from follow-on schedule check
