[2022-12-13T16:31:39.984+0000] {taskinstance.py:1087} INFO - Dependencies all met for <TaskInstance: bus_pos_etl.load_to_bq manual__2022-12-13T16:31:30.700268+00:00 [queued]>
[2022-12-13T16:31:39.998+0000] {taskinstance.py:1087} INFO - Dependencies all met for <TaskInstance: bus_pos_etl.load_to_bq manual__2022-12-13T16:31:30.700268+00:00 [queued]>
[2022-12-13T16:31:39.998+0000] {taskinstance.py:1283} INFO - 
--------------------------------------------------------------------------------
[2022-12-13T16:31:39.998+0000] {taskinstance.py:1284} INFO - Starting attempt 1 of 1
[2022-12-13T16:31:39.998+0000] {taskinstance.py:1285} INFO - 
--------------------------------------------------------------------------------
[2022-12-13T16:31:40.016+0000] {taskinstance.py:1304} INFO - Executing <Task(GCSToBigQueryOperator): load_to_bq> on 2022-12-13 16:31:30.700268+00:00
[2022-12-13T16:31:40.026+0000] {standard_task_runner.py:55} INFO - Started process 1099 to run task
[2022-12-13T16:31:40.031+0000] {standard_task_runner.py:82} INFO - Running: ['***', 'tasks', 'run', 'bus_pos_etl', 'load_to_bq', 'manual__2022-12-13T16:31:30.700268+00:00', '--job-id', '19', '--raw', '--subdir', 'DAGS_FOLDER/test_noe_bash.py', '--cfg-path', '/tmp/tmpwx5_35_w']
[2022-12-13T16:31:40.033+0000] {standard_task_runner.py:83} INFO - Job 19: Subtask load_to_bq
[2022-12-13T16:31:40.105+0000] {task_command.py:389} INFO - Running <TaskInstance: bus_pos_etl.load_to_bq manual__2022-12-13T16:31:30.700268+00:00 [running]> on host ff6f332d28b5
[2022-12-13T16:31:40.201+0000] {taskinstance.py:1513} INFO - Exporting the following env vars:
AIRFLOW_CTX_DAG_OWNER=noe
AIRFLOW_CTX_DAG_ID=bus_pos_etl
AIRFLOW_CTX_TASK_ID=load_to_bq
AIRFLOW_CTX_EXECUTION_DATE=2022-12-13T16:31:30.700268+00:00
AIRFLOW_CTX_TRY_NUMBER=1
AIRFLOW_CTX_DAG_RUN_ID=manual__2022-12-13T16:31:30.700268+00:00
[2022-12-13T16:31:40.225+0000] {taskinstance.py:1772} ERROR - Task failed with exception
Traceback (most recent call last):
  File "/home/airflow/.local/lib/python3.7/site-packages/airflow/providers/google/cloud/transfers/gcs_to_bigquery.py", line 296, in execute
    impersonation_chain=self.impersonation_chain,
  File "/home/airflow/.local/lib/python3.7/site-packages/airflow/providers/google/cloud/hooks/bigquery.py", line 103, in __init__
    impersonation_chain=impersonation_chain,
  File "/home/airflow/.local/lib/python3.7/site-packages/airflow/providers/google/common/hooks/base_google.py", line 231, in __init__
    self.extras: dict = self.get_connection(self.gcp_conn_id).extra_dejson
  File "/home/airflow/.local/lib/python3.7/site-packages/airflow/hooks/base.py", line 72, in get_connection
    conn = Connection.get_connection_from_secrets(conn_id)
  File "/home/airflow/.local/lib/python3.7/site-packages/airflow/models/connection.py", line 432, in get_connection_from_secrets
    raise AirflowNotFoundException(f"The conn_id `{conn_id}` isn't defined")
airflow.exceptions.AirflowNotFoundException: The conn_id `google_cloud_default` isn't defined
[2022-12-13T16:31:40.237+0000] {taskinstance.py:1327} INFO - Marking task as FAILED. dag_id=bus_pos_etl, task_id=load_to_bq, execution_date=20221213T163130, start_date=20221213T163139, end_date=20221213T163140
[2022-12-13T16:31:40.253+0000] {standard_task_runner.py:105} ERROR - Failed to execute job 19 for task load_to_bq (The conn_id `google_cloud_default` isn't defined; 1099)
[2022-12-13T16:31:40.284+0000] {local_task_job.py:159} INFO - Task exited with return code 1
[2022-12-13T16:31:40.308+0000] {taskinstance.py:2582} INFO - 0 downstream tasks scheduled from follow-on schedule check
