[2022-12-13T17:10:47.109+0000] {taskinstance.py:1087} INFO - Dependencies all met for <TaskInstance: incident_etl.load_to_bq manual__2022-12-13T17:10:38.753662+00:00 [queued]>
[2022-12-13T17:10:47.132+0000] {taskinstance.py:1087} INFO - Dependencies all met for <TaskInstance: incident_etl.load_to_bq manual__2022-12-13T17:10:38.753662+00:00 [queued]>
[2022-12-13T17:10:47.133+0000] {taskinstance.py:1283} INFO - 
--------------------------------------------------------------------------------
[2022-12-13T17:10:47.133+0000] {taskinstance.py:1284} INFO - Starting attempt 1 of 1
[2022-12-13T17:10:47.133+0000] {taskinstance.py:1285} INFO - 
--------------------------------------------------------------------------------
[2022-12-13T17:10:47.170+0000] {taskinstance.py:1304} INFO - Executing <Task(GCSToBigQueryOperator): load_to_bq> on 2022-12-13 17:10:38.753662+00:00
[2022-12-13T17:10:47.253+0000] {standard_task_runner.py:55} INFO - Started process 3065 to run task
[2022-12-13T17:10:47.261+0000] {standard_task_runner.py:82} INFO - Running: ['***', 'tasks', 'run', 'incident_etl', 'load_to_bq', 'manual__2022-12-13T17:10:38.753662+00:00', '--job-id', '44', '--raw', '--subdir', 'DAGS_FOLDER/dag_etl_incident.py', '--cfg-path', '/tmp/tmpcvda3ur9']
[2022-12-13T17:10:47.266+0000] {standard_task_runner.py:83} INFO - Job 44: Subtask load_to_bq
[2022-12-13T17:10:47.438+0000] {task_command.py:389} INFO - Running <TaskInstance: incident_etl.load_to_bq manual__2022-12-13T17:10:38.753662+00:00 [running]> on host ff6f332d28b5
[2022-12-13T17:10:47.548+0000] {taskinstance.py:1513} INFO - Exporting the following env vars:
AIRFLOW_CTX_DAG_OWNER=noe
AIRFLOW_CTX_DAG_ID=incident_etl
AIRFLOW_CTX_TASK_ID=load_to_bq
AIRFLOW_CTX_EXECUTION_DATE=2022-12-13T17:10:38.753662+00:00
AIRFLOW_CTX_TRY_NUMBER=1
AIRFLOW_CTX_DAG_RUN_ID=manual__2022-12-13T17:10:38.753662+00:00
[2022-12-13T17:10:47.563+0000] {base.py:73} INFO - Using connection ID 'google_cloud_default' for task execution.
[2022-12-13T17:10:47.581+0000] {base.py:73} INFO - Using connection ID 'google_cloud_default' for task execution.
[2022-12-13T17:10:47.582+0000] {gcs_to_bigquery.py:367} INFO - Using existing BigQuery table for storing data...
[2022-12-13T17:10:47.595+0000] {base.py:73} INFO - Using connection ID 'google_cloud_default' for task execution.
[2022-12-13T17:10:47.802+0000] {gcs.py:333} ERROR - Download attempt of object: bus_incident.csv from etl-***-incident-bucket has failed. Attempt: 1, max 1.
[2022-12-13T17:10:47.802+0000] {taskinstance.py:1772} ERROR - Task failed with exception
Traceback (most recent call last):
  File "/home/airflow/.local/lib/python3.7/site-packages/google/cloud/storage/client.py", line 1089, in download_blob_to_file
    retry=retry,
  File "/home/airflow/.local/lib/python3.7/site-packages/google/cloud/storage/blob.py", line 984, in _do_download
    response = download.consume(transport, timeout=timeout)
  File "/home/airflow/.local/lib/python3.7/site-packages/google/resumable_media/requests/download.py", line 233, in consume
    retriable_request, self._get_status_code, self._retry_strategy
  File "/home/airflow/.local/lib/python3.7/site-packages/google/resumable_media/requests/_request_helpers.py", line 148, in wait_and_retry
    response = func()
  File "/home/airflow/.local/lib/python3.7/site-packages/google/resumable_media/requests/download.py", line 214, in retriable_request
    self._process_response(result)
  File "/home/airflow/.local/lib/python3.7/site-packages/google/resumable_media/_download.py", line 189, in _process_response
    response, _ACCEPTABLE_STATUS_CODES, self._get_status_code
  File "/home/airflow/.local/lib/python3.7/site-packages/google/resumable_media/_helpers.py", line 113, in require_status_code
    *status_codes
google.resumable_media.common.InvalidResponse: ('Request failed with status code', 404, 'Expected one of', <HTTPStatus.OK: 200>, <HTTPStatus.PARTIAL_CONTENT: 206>)

During handling of the above exception, another exception occurred:

Traceback (most recent call last):
  File "/home/airflow/.local/lib/python3.7/site-packages/airflow/providers/google/cloud/transfers/gcs_to_bigquery.py", line 395, in execute
    self.configuration = self._check_schema_fields(self.configuration)
  File "/home/airflow/.local/lib/python3.7/site-packages/airflow/providers/google/cloud/transfers/gcs_to_bigquery.py", line 538, in _check_schema_fields
    object_name=source_object,
  File "/home/airflow/.local/lib/python3.7/site-packages/airflow/providers/google/cloud/hooks/gcs.py", line 324, in download
    return blob.download_as_bytes()
  File "/home/airflow/.local/lib/python3.7/site-packages/google/cloud/storage/blob.py", line 1401, in download_as_bytes
    retry=retry,
  File "/home/airflow/.local/lib/python3.7/site-packages/google/cloud/storage/client.py", line 1092, in download_blob_to_file
    _raise_from_invalid_response(exc)
  File "/home/airflow/.local/lib/python3.7/site-packages/google/cloud/storage/blob.py", line 4368, in _raise_from_invalid_response
    raise exceptions.from_http_status(response.status_code, message, response=response)
google.api_core.exceptions.NotFound: 404 GET https://storage.googleapis.com/download/storage/v1/b/etl-airflow-incident-bucket/o/bus_incident.csv?alt=media: No such object: etl-airflow-incident-bucket/bus_incident.csv: ('Request failed with status code', 404, 'Expected one of', <HTTPStatus.OK: 200>, <HTTPStatus.PARTIAL_CONTENT: 206>)
[2022-12-13T17:10:47.824+0000] {taskinstance.py:1327} INFO - Marking task as FAILED. dag_id=incident_etl, task_id=load_to_bq, execution_date=20221213T171038, start_date=20221213T171047, end_date=20221213T171047
[2022-12-13T17:10:47.847+0000] {standard_task_runner.py:105} ERROR - Failed to execute job 44 for task load_to_bq (404 GET https://storage.googleapis.com/download/storage/v1/b/etl-airflow-incident-bucket/o/bus_incident.csv?alt=media: No such object: etl-airflow-incident-bucket/bus_incident.csv: ('Request failed with status code', 404, 'Expected one of', <HTTPStatus.OK: 200>, <HTTPStatus.PARTIAL_CONTENT: 206>); 3065)
[2022-12-13T17:10:47.875+0000] {local_task_job.py:159} INFO - Task exited with return code 1
[2022-12-13T17:10:47.901+0000] {taskinstance.py:2582} INFO - 0 downstream tasks scheduled from follow-on schedule check
