[2022-12-13T16:19:50.387+0000] {taskinstance.py:1087} INFO - Dependencies all met for <TaskInstance: bus_pos_etl.etl_bus_loc scheduled__2022-12-12T00:00:00+00:00 [queued]>
[2022-12-13T16:19:50.403+0000] {taskinstance.py:1087} INFO - Dependencies all met for <TaskInstance: bus_pos_etl.etl_bus_loc scheduled__2022-12-12T00:00:00+00:00 [queued]>
[2022-12-13T16:19:50.404+0000] {taskinstance.py:1283} INFO - 
--------------------------------------------------------------------------------
[2022-12-13T16:19:50.404+0000] {taskinstance.py:1284} INFO - Starting attempt 1 of 1
[2022-12-13T16:19:50.404+0000] {taskinstance.py:1285} INFO - 
--------------------------------------------------------------------------------
[2022-12-13T16:19:50.420+0000] {taskinstance.py:1304} INFO - Executing <Task(BashOperator): etl_bus_loc> on 2022-12-12 00:00:00+00:00
[2022-12-13T16:19:50.434+0000] {standard_task_runner.py:55} INFO - Started process 447 to run task
[2022-12-13T16:19:50.438+0000] {standard_task_runner.py:82} INFO - Running: ['***', 'tasks', 'run', 'bus_pos_etl', 'etl_bus_loc', 'scheduled__2022-12-12T00:00:00+00:00', '--job-id', '11', '--raw', '--subdir', 'DAGS_FOLDER/test_noe_bash.py', '--cfg-path', '/tmp/tmp2j8dltmv']
[2022-12-13T16:19:50.439+0000] {standard_task_runner.py:83} INFO - Job 11: Subtask etl_bus_loc
[2022-12-13T16:19:50.553+0000] {task_command.py:389} INFO - Running <TaskInstance: bus_pos_etl.etl_bus_loc scheduled__2022-12-12T00:00:00+00:00 [running]> on host ff6f332d28b5
[2022-12-13T16:19:50.647+0000] {taskinstance.py:1513} INFO - Exporting the following env vars:
AIRFLOW_CTX_DAG_OWNER=noe
AIRFLOW_CTX_DAG_ID=bus_pos_etl
AIRFLOW_CTX_TASK_ID=etl_bus_loc
AIRFLOW_CTX_EXECUTION_DATE=2022-12-12T00:00:00+00:00
AIRFLOW_CTX_TRY_NUMBER=1
AIRFLOW_CTX_DAG_RUN_ID=scheduled__2022-12-12T00:00:00+00:00
[2022-12-13T16:19:50.649+0000] {subprocess.py:63} INFO - Tmp dir root location: 
 /tmp
[2022-12-13T16:19:50.650+0000] {subprocess.py:75} INFO - Running command: ['/bin/bash', '-c', 'python /opt/***/etl/etl.py']
[2022-12-13T16:19:50.703+0000] {subprocess.py:86} INFO - Output:
[2022-12-13T16:19:50.743+0000] {subprocess.py:93} INFO - python: can't open file '/opt/***/etl/etl.py': [Errno 2] No such file or directory
[2022-12-13T16:19:50.762+0000] {subprocess.py:97} INFO - Command exited with return code 2
[2022-12-13T16:19:50.785+0000] {taskinstance.py:1772} ERROR - Task failed with exception
Traceback (most recent call last):
  File "/home/airflow/.local/lib/python3.7/site-packages/airflow/operators/bash.py", line 197, in execute
    f"Bash command failed. The command returned a non-zero exit code {result.exit_code}."
airflow.exceptions.AirflowException: Bash command failed. The command returned a non-zero exit code 2.
[2022-12-13T16:19:50.795+0000] {taskinstance.py:1327} INFO - Marking task as FAILED. dag_id=bus_pos_etl, task_id=etl_bus_loc, execution_date=20221212T000000, start_date=20221213T161950, end_date=20221213T161950
[2022-12-13T16:19:50.835+0000] {standard_task_runner.py:105} ERROR - Failed to execute job 11 for task etl_bus_loc (Bash command failed. The command returned a non-zero exit code 2.; 447)
[2022-12-13T16:19:50.893+0000] {local_task_job.py:159} INFO - Task exited with return code 1
[2022-12-13T16:19:50.949+0000] {taskinstance.py:2582} INFO - 0 downstream tasks scheduled from follow-on schedule check
