[2022-12-13T16:45:31.377+0000] {taskinstance.py:1087} INFO - Dependencies all met for <TaskInstance: incident_etl.etl_incident scheduled__2022-12-12T00:00:00+00:00 [queued]>
[2022-12-13T16:45:31.395+0000] {taskinstance.py:1087} INFO - Dependencies all met for <TaskInstance: incident_etl.etl_incident scheduled__2022-12-12T00:00:00+00:00 [queued]>
[2022-12-13T16:45:31.395+0000] {taskinstance.py:1283} INFO - 
--------------------------------------------------------------------------------
[2022-12-13T16:45:31.395+0000] {taskinstance.py:1284} INFO - Starting attempt 1 of 1
[2022-12-13T16:45:31.395+0000] {taskinstance.py:1285} INFO - 
--------------------------------------------------------------------------------
[2022-12-13T16:45:31.418+0000] {taskinstance.py:1304} INFO - Executing <Task(BashOperator): etl_incident> on 2022-12-12 00:00:00+00:00
[2022-12-13T16:45:31.429+0000] {standard_task_runner.py:55} INFO - Started process 1732 to run task
[2022-12-13T16:45:31.436+0000] {standard_task_runner.py:82} INFO - Running: ['***', 'tasks', 'run', 'incident_etl', 'etl_incident', 'scheduled__2022-12-12T00:00:00+00:00', '--job-id', '24', '--raw', '--subdir', 'DAGS_FOLDER/dag_etl_incident.py', '--cfg-path', '/tmp/tmpwqt2q24k']
[2022-12-13T16:45:31.438+0000] {standard_task_runner.py:83} INFO - Job 24: Subtask etl_incident
[2022-12-13T16:45:31.525+0000] {task_command.py:389} INFO - Running <TaskInstance: incident_etl.etl_incident scheduled__2022-12-12T00:00:00+00:00 [running]> on host ff6f332d28b5
[2022-12-13T16:45:31.646+0000] {taskinstance.py:1513} INFO - Exporting the following env vars:
AIRFLOW_CTX_DAG_OWNER=noe
AIRFLOW_CTX_DAG_ID=incident_etl
AIRFLOW_CTX_TASK_ID=etl_incident
AIRFLOW_CTX_EXECUTION_DATE=2022-12-12T00:00:00+00:00
AIRFLOW_CTX_TRY_NUMBER=1
AIRFLOW_CTX_DAG_RUN_ID=scheduled__2022-12-12T00:00:00+00:00
[2022-12-13T16:45:31.653+0000] {subprocess.py:63} INFO - Tmp dir root location: 
 /tmp
[2022-12-13T16:45:31.656+0000] {subprocess.py:75} INFO - Running command: ['/bin/bash', '-c', 'python /opt/***/dags/etl/etl_incident.py']
[2022-12-13T16:45:31.700+0000] {subprocess.py:86} INFO - Output:
[2022-12-13T16:45:32.692+0000] {subprocess.py:93} INFO - Traceback (most recent call last):
[2022-12-13T16:45:32.693+0000] {subprocess.py:93} INFO -   File "/opt/***/dags/etl/etl_incident.py", line 5, in <module>
[2022-12-13T16:45:32.693+0000] {subprocess.py:93} INFO -     import geopandas as gpd
[2022-12-13T16:45:32.693+0000] {subprocess.py:93} INFO - ModuleNotFoundError: No module named 'geopandas'
[2022-12-13T16:45:32.864+0000] {subprocess.py:97} INFO - Command exited with return code 1
[2022-12-13T16:45:32.882+0000] {taskinstance.py:1772} ERROR - Task failed with exception
Traceback (most recent call last):
  File "/home/airflow/.local/lib/python3.7/site-packages/airflow/operators/bash.py", line 197, in execute
    f"Bash command failed. The command returned a non-zero exit code {result.exit_code}."
airflow.exceptions.AirflowException: Bash command failed. The command returned a non-zero exit code 1.
[2022-12-13T16:45:32.891+0000] {taskinstance.py:1327} INFO - Marking task as FAILED. dag_id=incident_etl, task_id=etl_incident, execution_date=20221212T000000, start_date=20221213T164531, end_date=20221213T164532
[2022-12-13T16:45:32.920+0000] {standard_task_runner.py:105} ERROR - Failed to execute job 24 for task etl_incident (Bash command failed. The command returned a non-zero exit code 1.; 1732)
[2022-12-13T16:45:32.932+0000] {local_task_job.py:159} INFO - Task exited with return code 1
[2022-12-13T16:45:32.962+0000] {taskinstance.py:2582} INFO - 0 downstream tasks scheduled from follow-on schedule check
